Workbook

Sheet Resumen
A1: Resumen General - Control de Prestamos
A2: Dias de gracia antes de marcar Atrasado | B2: 3 | C2: Supuesto ajustable: dias extra de tolerancia sumados al ciclo de pago antes de marcar un prestamo como Atrasado.
A4: Indicador | B4: Valor
A5: Total prestado (historico) | B5: =SUM(Prestamos!D2:D400)
A6: Capital pendiente actual | B6: =SUM(Prestamos!G2:G400)
A7: Total cobrado (capital+interes) | B7: =SUM(Prestamos!H2:H400)
A8: Interes total cobrado | B8: =SUM(Prestamos!I2:I400)
A9: Prestamos activos | B9: =COUNTIFS(Prestamos!A2:A400,"<>",Prestamos!M2:M400,"<>Pagado")
A10: Prestamos atrasados | B10: =COUNTIF(Prestamos!M2:M400,"Atrasado")
A11: Prestamos pagados | B11: =COUNTIF(Prestamos!M2:M400,"Pagado")
A13: Consejo: usa el filtro (flecha en el encabezado) de la pestana Prestamos, columna Estado, para ver solo los Atrasados.

Sheet Instrucciones
A1: Control de Prestamos - Guia rapida
A3: Este libro reemplaza el registro manual de prestamos en Excel por uno con formulas automaticas.
A5: Como funciona el calculo de interes (segun lo que me indicaste):
A6: - Cada prestamo tiene su propia tasa de interes por periodo (columna Tasa en la pestana Prestamos).
A7: - Cada vez que registras un pago en la pestana Pagos, el sistema calcula el interes sobre el saldo
A8: pendiente de ESE prestamo (saldo x tasa).
A9: - Si el pago es mayor al interes, la diferencia abona a capital y el saldo baja.
A10: - Si el pago es menor o igual al interes, no se abona nada a capital ese periodo (el saldo no baja).
A11: Supuesto: el interes no cubierto NO se acumula ni genera interes sobre interes.
A13: Colores (mismo criterio en todas las pestanas):
A14: Texto azul = tu escribes aqui (dato de entrada)
A15: Texto negro = formula automatica, no la edites
... A35: montos o saldos con dinero real de por medio.

Sheet Prestamos
A1: ID Prestamo | B1: Cliente | C1: Fecha inicio | D1: Monto prestado | E1: Tasa interes (%/periodo) | F1: Frecuencia de pago | G1: Saldo pendiente | H1: Total pagado | I1: Interes cobrado | J1: Fecha ultimo pago | K1: Dias desde referencia | L1: Dias max permitidos | M1: Estado
A2: =IF(B2="","","P"&TEXT(ROW()-1,"000")) | B2: Cliente Ejemplo | C2: 2026-06-01 | D2: 100000 | E2: 0.1 | F2: Quincenal | G2: =IF(B2="","",D2-SUMIFS(Pagos!$H:$H,Pagos!$B:$B,A2)) | H2: =IF(B2="","",SUMIFS(Pagos!$E:$E,Pagos!$B:$B,A2)) | I2: =IF(B2="","",SUMIFS(Pagos!$G:$G,Pagos!$B:$B,A2)) | J2: =IF(B2="","",IF(COUNTIF(Pagos!$B:$B,A2)=0,"",_xlfn.MAXIFS(Pagos!$D:$D,Pagos!$B:$B,A2))) | K2: =IF(B2="","",IF(J2="",TODAY()-C2,TODAY()-J2)) | L2: =IF(B2="","",IF(F2="Diario",1,IF(F2="Semanal",7,IF(F2="Quincenal",15,IF(F2="Mensual",30,30))))+Resumen!$B$2) | M2: =IF(B2="","",IF(G2<=0,"Pagado",IF(K2>L2,"Atrasado","Al dia")))
A3: =IF(B3="","","P"&TEXT(ROW()-1,"000")) | G3: =IF(B3="","",D3-SUMIFS(Pagos!$H:$H,Pagos!$B:$B,A3)) | H3: =IF(B3="","",SUMIFS(Pagos!$E:$E,Pagos!$B:$B,A3)) | I3: =IF(B3="","",SUMIFS(Pagos!$G:$G,Pagos!$B:$B,A3)) | J3: =IF(B3="","",IF(COUNTIF(Pagos!$B:$B,A3)=0,"",_xlfn.MAXIFS(Pagos!$D:$D,Pagos!$B:$B,A3))) | K3: =IF(B3="","",IF(J3="",TODAY()-C3,TODAY()-J3)) | L3: =IF(B3="","",IF(F3="Diario",1,IF(F3="Semanal",7,IF(F3="Quincenal",15,IF(F3="Mensual",30,30))))+Resumen!$B$2) | M3: =IF(B3="","",IF(G3<=0,"Pagado",IF(K3>L3,"Atrasado","Al dia")))
A4: =IF(B4="","","P"&TEXT(ROW()-1,"000")) | G4: =IF(B4="","",D4-SUMIFS(Pagos!$H:$H,Pagos!$B:$B,A4)) | H4: =IF(B4="","",SUMIFS(Pagos!$E:$E,Pagos!$B:$B,A4)) | I4: =IF(B4="","",SUMIFS(Pagos!$G:$G,Pagos!$B:$B,A4)) | J4: =IF(B4="","",IF(COUNTIF(Pagos!$B:$B,A4)=0,"",_xlfn.MAXIFS(Pagos!$D:$D,Pagos!$B:$B,A4))) | K4: =IF(B4="","",IF(J4="",TODAY()-C4,TODAY()-J4)) | L4: =IF(B4="","",IF(F4="Diario",1,IF(F4="Semanal",7,IF(F4="Quincenal",15,IF(F4="Mensual",30,30))))+Resumen!$B$2) | M4: =IF(B4="","",IF(G4<=0,"Pagado",IF(K4>L4,"Atrasado","Al dia")))
A5: =IF(B5="","","P"&TEXT(ROW()-1,"000")) | G5: =IF(B5="","",D5-SUMIFS(Pagos!$H:$H,Pagos!$B:$B,A5)) | H5: =IF(B5="","",SUMIFS(Pagos!$E:$E,Pagos!$B:$B,A5)) | I5: =IF(B5="","",SUMIFS(Pagos!$G:$G,Pagos!$B:$B,A5)) | J5: =IF(B5="","",IF(COUNTIF(Pagos!$B:$B,A5)=0,"",_xlfn.MAXIFS(Pagos!$D:$D,Pagos!$B:$B,A5))) | K5: =IF(B5="","",IF(J5="",TODAY()-C5,TODAY()-J5)) | L5: =IF(B5="","",IF(F5="Diario",1,IF(F5="Semanal",7,IF(F5="Quincenal",15,IF(F5="Mensual",30,30))))+Resumen!$B$2) | M5: =IF(B5="","",IF(G5<=0,"Pagado",IF(K5>L5,"Atrasado","Al dia")))
A6: =IF(B6="","","P"&TEXT(ROW()-1,"000")) | G6: =IF(B6="","",D6-SUMIFS(Pagos!$H:$H,Pagos!$B:$B,A6)) | H6: =IF(B6="","",SUMIFS(Pagos!$E:$E,Pagos!$B:$B,A6)) | I6: =IF(B6="","",SUMIFS(Pagos!$G:$G,Pagos!$B:$B,A6)) | J6: =IF(B6="","",IF(COUNTIF(Pagos!$B:$B,A6)=0,"",_xlfn.MAXIFS(Pagos!$D:$D,Pagos!$B:$B,A6))) | K6: =IF(B6="","",IF(J6="",TODAY()-C6,TODAY()-J6)) | L6: =IF(B6="","",IF(F6="Diario",1,IF(F6="Semanal",7,IF(F6="Quincenal",15,IF(F6="Mensual",30,30))))+Resumen!$B$2) | M6: =IF(B6="","",IF(G6<=0,"Pagado",IF(K6>L6,"Atrasado","Al dia")))
A7: =IF(B7="","","P"&TEXT(ROW()-1,"000")) | G7: =IF(B7="","",D7-SUMIFS(Pagos!$H:$H,Pagos!$B:$B,A7)) | H7: =IF(B7="","",SUMIFS(Pagos!$E:$E,Pagos!$B:$B,A7)) | I7: =IF(B7="","",SUMIFS(Pagos!$G:$G,Pagos!$B:$B,A7)) | J7: =IF(B7="","",IF(COUNTIF(Pagos!$B:$B,A7)=0,"",_xlfn.MAXIFS(Pagos!$D:$D,Pagos!$B:$B,A7))) | K7: =IF(B7="","",IF(J7="",TODAY()-C7,TODAY()-J7)) | L7: =IF(B7="","",IF(F7="Diario",1,IF(F7="Semanal",7,IF(F7="Quincenal",15,IF(F7="Mensual",30,30))))+Resumen!$B$2) | M7: =IF(B7="","",IF(G7<=0,"Pagado",IF(K7>L7,"Atrasado","Al dia")))
A8: =IF(B8="","","P"&TEXT(ROW()-1,"000")) | G8: =IF(B8="","",D8-SUMIFS(Pagos!$H:$H,Pagos!$B:$B,A8)) | H8: =IF(B8="","",SUMIFS(Pagos!$E:$E,Pagos!$B:$B,A8)) | I8: =IF(B8="","",SUMIFS(Pagos!$G:$G,Pagos!$B:$B,A8)) | J8: =IF(B8="","",IF(COUNTIF(Pagos!$B:$B,A8)=0,"",_xlfn.MAXIFS(Pagos!$D:$D,Pagos!$B:$B,A8))) | K8: =IF(B8="","",IF(J8="",TODAY()-C8,TODAY()-J8)) | L8: =IF(B8="","",IF(F8="Diario",1,IF(F8="Semanal",7,IF(F8="Quincenal",15,IF(F8="Mensual",30,30))))+Resumen!$B$2) | M8: =IF(B8="","",IF(G8<=0,"Pagado",IF(K8>L8,"Atrasado","Al dia")))
A9: =IF(B9="","","P"&TEXT(ROW()-1,"000")) | G9: =IF(B9="","",D9-SUMIFS(Pagos!$H:$H,Pagos!$B:$B,A9)) | H9: =IF(B9="","",SUMIFS(Pagos!$E:$E,Pagos!$B:$B,A9)) | I9: =IF(B9="","",SUMIFS(Pagos!$G:$G,Pagos!$B:$B,A9)) | J9: =IF(B9="","",IF(COUNTIF(Pagos!$B:$B,A9)=0,"",_xlfn.MAXIFS(Pagos!$D:$D,Pagos!$B:$B,A9))) | K9: =IF(B9="","",IF(J9="",TODAY()-C9,TODAY()-J9)) | L9: =IF(B9="","",IF(F9="Diario",1,IF(F9="Semanal",7,IF(F9="Quincenal",15,IF(F9="Mensual",30,30))))+Resumen!$B$2) | M9: =IF(B9="","",IF(G9<=0,"Pagado",IF(K9>L9,"Atrasado","Al dia")))
A10: =IF(B10="","","P"&TEXT(ROW()-1,"000")) | G10: =IF(B10="","",D10-SUMIFS(Pagos!$H:$H,Pagos!$B:$B,A10)) | H10: =IF(B10="","",SUMIFS(Pagos!$E:$E,Pagos!$B:$B,A10)) | I10: =IF(B10="","",SUMIFS(Pagos!$G:$G,Pagos!$B:$B,A10)) | J10: =IF(B10="","",IF(COUNTIF(Pagos!$B:$B,A10)=0,"",_xlfn.MAXIFS(Pagos!$D:$D,Pagos!$B:$B,A10))) | K10: =IF(B10="","",IF(J10="",TODAY()-C10,TODAY()-J10)) | L10: =IF(B10="","",IF(F10="Diario",1,IF(F10="Semanal",7,IF(F10="Quincenal",15,IF(F10="Mensual",30,30))))+Resumen!$B$2) | M10: =IF(B10="","",IF(G10<=0,"Pagado",IF(K10>L10,"Atrasado","Al dia")))
A11: =IF(B11="","","P"&TEXT(ROW()-1,"000")) | G11: =IF(B11="","",D11-SUMIFS(Pagos!$H:$H,Pagos!$B:$B,A11)) | H11: =IF(B11="","",SUMIFS(Pagos!$E:$E,Pagos!$B:$B,A11)) | I11: =IF(B11="","",SUMIFS(Pagos!$G:$G,Pagos!$B:$B,A11)) | J11: =IF(B11="","",IF(COUNTIF(Pagos!$B:$B,A11)=0,"",_xlfn.MAXIFS(Pagos!$D:$D,Pagos!$B:$B,A11))) | K11: =IF(B11="","",IF(J11="",TODAY()-C11,TODAY()-J11)) | L11: =IF(B11="","",IF(F11="Diario",1,IF(F11="Semanal",7,IF(F11="Quincenal",15,IF(F11="Mensual",30,30))))+Resumen!$B$2) | M11: =IF(B11="","",IF(G11<=0,"Pagado",IF(K11>L11,"Atrasado","Al dia")))
A12: =IF(B12="","","P"&TEXT(ROW()-1,"000")) | G12: =IF(B12="","",D12-SUMIFS(Pagos!$H:$H,Pagos!$B:$B,A12)) | H12: =IF(B12="","",SUMIFS(Pagos!$E:$E,Pagos!$B:$B,A12)) | I12: =IF(B12="","",SUMIFS(Pagos!$G:$G,Pagos!$B:$B,A12)) | J12: =IF(B12="","",IF(COUNTIF(Pagos!$B:$B,A12)=0,"",_xlfn.MAXIFS(Pagos!$D:$D,Pagos!$B:$B,A12))) | K12: =IF(B12="","",IF(J12="",TODAY()-C12,TODAY()-J12)) | L12: =IF(B12="","",IF(F12="Diario",1,IF(F12="Semanal",7,IF(F12="Quincenal",15,IF(F12="Mensual",30,30))))+Resumen!$B$2) | M12: =IF(B12="","",IF(G12<=0,"Pagado",IF(K12>L12,"Atrasado","Al dia")))
A13: =IF(B13="","","P"&TEXT(ROW()-1,"000")) | G13: =IF(B13="","",D13-SUMIFS(Pagos!$H:$H,Pagos!$B:$B,A13)) | H13: =IF(B13="","",SUMIFS(Pagos!$E:$E,Pagos!$B:$B,A13)) | I13: =IF(B13="","",SUMIFS(Pagos!$G:$G,Pagos!$B:$B,A13)) | J13: =IF(B13="","",IF(COUNTIF(Pagos!$B:$B,A13)=0,"",_xlfn.MAXIFS(Pagos!$D:$D,Pagos!$B:$B,A13))) | K13: =IF(B13="","",IF(J13="",TODAY()-C13,TODAY()-J13)) | L13: =IF(B13="","",IF(F13="Diario",1,IF(F13="Semanal",7,IF(F13="Quincenal",15,IF(F13="Mensual",30,30))))+Resumen!$B$2) | M13: =IF(B13="","",IF(G13<=0,"Pagado",IF(K13>L13,"Atrasado","Al dia")))
A14: =IF(B14="","","P"&TEXT(ROW()-1,"000")) | G14: =IF(B14="","",D14-SUMIFS(Pagos!$H:$H,Pagos!$B:$B,A14)) | H14: =IF(B14="","",SUMIFS(Pagos!$E:$E,Pagos!$B:$B,A14)) | I14: =IF(B14="","",SUMIFS(Pagos!$G:$G,Pagos!$B:$B,A14)) | J14: =IF(B14="","",IF(COUNTIF(Pagos!$B:$B,A14)=0,"",_xlfn.MAXIFS(Pagos!$D:$D,Pagos!$B:$B,A14))) | K14: =IF(B14="","",IF(J14="",TODAY()-C14,TODAY()-J14)) | L14: =IF(B14="","",IF(F14="Diario",1,IF(F14="Semanal",7,IF(F14="Quincenal",15,IF(F14="Mensual",30,30))))+Resumen!$B$2) | M14: =IF(B14="","",IF(G14<=0,"Pagado",IF(K14>L14,"Atrasado","Al dia")))
... A400: =IF(B400="","","P"&TEXT(ROW()-1,"000")) | G400: =IF(B400="","",D400-SUMIFS(Pagos!$H:$H,Pagos!$B:$B,A400)) | H400: =IF(B400="","",SUMIFS(Pagos!$E:$E,Pagos!$B:$B,A400)) | I400: =IF(B400="","",SUMIFS(Pagos!$G:$G,Pagos!$B:$B,A400)) | J400: =IF(B400="","",IF(COUNTIF(Pagos!$B:$B,A400)=0,"",_xlfn.MAXIFS(Pagos!$D:$D,Pagos!$B:$B,A400))) | K400: =IF(B400="","",IF(J400="",TODAY()-C400,TODAY()-J400)) | L400: =IF(B400="","",IF(F400="Diario",1,IF(F400="Semanal",7,IF(F400="Quincenal",15,IF(F400="Mensual",30,30))))+Resumen!$B$2) | M400: =IF(B400="","",IF(G400<=0,"Pagado",IF(K400>L400,"Atrasado","Al dia")))

Sheet Pagos
A1: ID Pago | B1: ID Prestamo | C1: Cliente | D1: Fecha de pago | E1: Monto pagado | F1: Saldo anterior | G1: Interes del periodo | H1: Abono a capital | I1: Saldo nuevo
A2: =IF(B2="","","PG"&TEXT(ROW()-1,"0000")) | B2: P001 | C2: =IF(B2="","",INDEX(Prestamos!$B:$B,MATCH(B2,Prestamos!$A:$A,0))) | D2: 2026-06-15 | E2: 15000 | F2: =IF(B2="","",INDEX(Prestamos!$D:$D,MATCH(B2,Prestamos!$A:$A,0))-SUMIFS($H$1:H1,$B$1:B1,B2)) | G2: =IF(B2="","",F2*INDEX(Prestamos!$E:$E,MATCH(B2,Prestamos!$A:$A,0))) | H2: =IF(B2="","",MAX(0,E2-G2)) | I2: =IF(B2="","",F2-H2)
A3: =IF(B3="","","PG"&TEXT(ROW()-1,"0000")) | B3: P001 | C3: =IF(B3="","",INDEX(Prestamos!$B:$B,MATCH(B3,Prestamos!$A:$A,0))) | D3: 2026-06-30 | E3: 12000 | F3: =IF(B3="","",INDEX(Prestamos!$D:$D,MATCH(B3,Prestamos!$A:$A,0))-SUMIFS($H$1:H1,$B$1:B1,B3)) | G3: =IF(B3="","",F3*INDEX(Prestamos!$E:$E,MATCH(B3,Prestamos!$A:$A,0))) | H3: =IF(B3="","",MAX(0,E3-G3)) | I3: =IF(B3="","",F3-H3)
A4: =IF(B4="","","PG"&TEXT(ROW()-1,"0000")) | C4: =IF(B4="","",INDEX(Prestamos!$B:$B,MATCH(B4,Prestamos!$A:$A,0))) | F4: =IF(B4="","",INDEX(Prestamos!$D:$D,MATCH(B4,Prestamos!$A:$A,0))-SUMIFS($H$1:H1,$B$1:B1,B4)) | G4: =IF(B4="","",F4*INDEX(Prestamos!$E:$E,MATCH(B4,Prestamos!$A:$A,0))) | H4: =IF(B4="","",MAX(0,E4-G4)) | I4: =IF(B4="","",F4-H4)
A5: =IF(B5="","","PG"&TEXT(ROW()-1,"0000")) | C5: =IF(B5="","",INDEX(Prestamos!$B:$B,MATCH(B5,Prestamos!$A:$A,0))) | F5: =IF(B5="","",INDEX(Prestamos!$D:$D,MATCH(B5,Prestamos!$A:$A,0))-SUMIFS($H$1:H1,$B$1:B1,B5)) | G5: =IF(B5="","",F5*INDEX(Prestamos!$E:$E,MATCH(B5,Prestamos!$A:$A,0))) | H5: =IF(B5="","",MAX(0,E5-G5)) | I5: =IF(B5="","",F5-H5)
A6: =IF(B6="","","PG"&TEXT(ROW()-1,"0000")) | C6: =IF(B6="","",INDEX(Prestamos!$B:$B,MATCH(B6,Prestamos!$A:$A,0))) | F6: =IF(B6="","",INDEX(Prestamos!$D:$D,MATCH(B6,Prestamos!$A:$A,0))-SUMIFS($H$1:H1,$B$1:B1,B6)) | G6: =IF(B6="","",F6*INDEX(Prestamos!$E:$E,MATCH(B6,Prestamos!$A:$A,0))) | H6: =IF(B6="","",MAX(0,E6-G6)) | I6: =IF(B6="","",F6-H6)
A7: =IF(B7="","","PG"&TEXT(ROW()-1,"0000")) | C7: =IF(B7="","",INDEX(Prestamos!$B:$B,MATCH(B7,Prestamos!$A:$A,0))) | F7: =IF(B7="","",INDEX(Prestamos!$D:$D,MATCH(B7,Prestamos!$A:$A,0))-SUMIFS($H$1:H1,$B$1:B1,B7)) | G7: =IF(B7="","",F7*INDEX(Prestamos!$E:$E,MATCH(B7,Prestamos!$A:$A,0))) | H7: =IF(B7="","",MAX(0,E7-G7)) | I7: =IF(B7="","",F7-H7)
A8: =IF(B8="","","PG"&TEXT(ROW()-1,"0000")) | C8: =IF(B8="","",INDEX(Prestamos!$B:$B,MATCH(B8,Prestamos!$A:$A,0))) | F8: =IF(B8="","",INDEX(Prestamos!$D:$D,MATCH(B8,Prestamos!$A:$A,0))-SUMIFS($H$1:H1,$B$1:B1,B8)) | G8: =IF(B8="","",F8*INDEX(Prestamos!$E:$E,MATCH(B8,Prestamos!$A:$A,0))) | H8: =IF(B8="","",MAX(0,E8-G8)) | I8: =IF(B8="","",F8-H8)
A9: =IF(B9="","","PG"&TEXT(ROW()-1,"0000")) | C9: =IF(B9="","",INDEX(Prestamos!$B:$B,MATCH(B9,Prestamos!$A:$A,0))) | F9: =IF(B9="","",INDEX(Prestamos!$D:$D,MATCH(B9,Prestamos!$A:$A,0))-SUMIFS($H$1:H1,$B$1:B1,B9)) | G9: =IF(B9="","",F9*INDEX(Prestamos!$E:$E,MATCH(B9,Prestamos!$A:$A,0))) | H9: =IF(B9="","",MAX(0,E9-G9)) | I9: =IF(B9="","",F9-H9)
A10: =IF(B10="","","PG"&TEXT(ROW()-1,"0000")) | C10: =IF(B10="","",INDEX(Prestamos!$B:$B,MATCH(B10,Prestamos!$A:$A,0))) | F10: =IF(B10="","",INDEX(Prestamos!$D:$D,MATCH(B10,Prestamos!$A:$A,0))-SUMIFS($H$1:H1,$B$1:B1,B10)) | G10: =IF(B10="","",F10*INDEX(Prestamos!$E:$E,MATCH(B10,Prestamos!$A:$A,0))) | H10: =IF(B10="","",MAX(0,E10-G10)) | I10: =IF(B10="","",F10-H10)
A11: =IF(B11="","","PG"&TEXT(ROW()-1,"0000")) | C11: =IF(B11="","",INDEX(Prestamos!$B:$B,MATCH(B11,Prestamos!$A:$A,0))) | F11: =IF(B11="","",INDEX(Prestamos!$D:$D,MATCH(B11,Prestamos!$A:$A,0))-SUMIFS($H$1:H1,$B$1:B1,B11)) | G11: =IF(B11="","",F11*INDEX(Prestamos!$E:$E,MATCH(B11,Prestamos!$A:$A,0))) | H11: =IF(B11="","",MAX(0,E11-G11)) | I11: =IF(B11="","",F11-H11)
A12: =IF(B12="","","PG"&TEXT(ROW()-1,"0000")) | C12: =IF(B12="","",INDEX(Prestamos!$B:$B,MATCH(B12,Prestamos!$A:$A,0))) | F12: =IF(B12="","",INDEX(Prestamos!$D:$D,MATCH(B12,Prestamos!$A:$A,0))-SUMIFS($H$1:H1,$B$1:B1,B12)) | G12: =IF(B12="","",F12*INDEX(Prestamos!$E:$E,MATCH(B12,Prestamos!$A:$A,0))) | H12: =IF(B12="","",MAX(0,E12-G12)) | I12: =IF(B12="","",F12-H12)
A13: =IF(B13="","","PG"&TEXT(ROW()-1,"0000")) | C13: =IF(B13="","",INDEX(Prestamos!$B:$B,MATCH(B13,Prestamos!$A:$A,0))) | F13: =IF(B13="","",INDEX(Prestamos!$D:$D,MATCH(B13,Prestamos!$A:$A,0))-SUMIFS($H$1:H1,$B$1:B1,B13)) | G13: =IF(B13="","",F13*INDEX(Prestamos!$E:$E,MATCH(B13,Prestamos!$A:$A,0))) | H13: =IF(B13="","",MAX(0,E13-G13)) | I13: =IF(B13="","",F13-H13)
A14: =IF(B14="","","PG"&TEXT(ROW()-1,"0000")) | C14: =IF(B14="","",INDEX(Prestamos!$B:$B,MATCH(B14,Prestamos!$A:$A,0))) | F14: =IF(B14="","",INDEX(Prestamos!$D:$D,MATCH(B14,Prestamos!$A:$A,0))-SUMIFS($H$1:H1,$B$1:B1,B14)) | G14: =IF(B14="","",F14*INDEX(Prestamos!$E:$E,MATCH(B14,Prestamos!$A:$A,0))) | H14: =IF(B14="","",MAX(0,E14-G14)) | I14: =IF(B14="","",F14-H14)
A15: =IF(B15="","","PG"&TEXT(ROW()-1,"0000")) | C15: =IF(B15="","",INDEX(Prestamos!$B:$B,MATCH(B15,Prestamos!$A:$A,0))) | F15: =IF(B15="","",INDEX(Prestamos!$D:$D,MATCH(B15,Prestamos!$A:$A,0))-SUMIFS($H$1:H1,$B$1:B1,B15)) | G15: =IF(B15="","",F15*INDEX(Prestamos!$E:$E,MATCH(B15,Prestamos!$A:$A,0))) | H15: =IF(B15="","",MAX(0,E15-G15)) | I15: =IF(B15="","",F15-H15)
A16: =IF(B16="","","PG"&TEXT(ROW()-1,"0000")) | C16: =IF(B16="","",INDEX(Prestamos!$B:$B,MATCH(B16,Prestamos!$A:$A,0))) | F16: =IF(B16="","",INDEX(Prestamos!$D:$D,MATCH(B16,Prestamos!$A:$A,0))-SUMIFS($H$1:H1,$B$1:B1,B16)) | G16: =IF(B16="","",F16*INDEX(Prestamos!$E:$E,MATCH(B16,Prestamos!$A:$A,0))) | H16: =IF(B16="","",MAX(0,E16-G16)) | I16: =IF(B16="","",F16-H16)
A17: =IF(B17="","","PG"&TEXT(ROW()-1,"0000")) | C17: =IF(B17="","",INDEX(Prestamos!$B:$B,MATCH(B17,Prestamos!$A:$A,0))) | F17: =IF(B17="","",INDEX(Prestamos!$D:$D,MATCH(B17,Prestamos!$A:$A,0))-SUMIFS($H$1:H1,$B$1:B1,B17)) | G17: =IF(B17="","",F17*INDEX(Prestamos!$E:$E,MATCH(B17,Prestamos!$A:$A,0))) | H17: =IF(B17="","",MAX(0,E17-G17)) | I17: =IF(B17="","",F17-H17)
A18: =IF(B18="","","PG"&TEXT(ROW()-1,"0000")) | C18: =IF(B18="","",INDEX(Prestamos!$B:$B,MATCH(B18,Prestamos!$A:$A,0))) | F18: =IF(B18="","",INDEX(Prestamos!$D:$D,MATCH(B18,Prestamos!$A:$A,0))-SUMIFS($H$1:H1,$B$1:B1,B18)) | G18: =IF(B18="","",F18*INDEX(Prestamos!$E:$E,MATCH(B18,Prestamos!$A:$A,0))) | H18: =IF(B18="","",MAX(0,E18-G18)) | I18: =IF(B18="","",F18-H18)
A19: =IF(B19="","","PG"&TEXT(ROW()-1,"0000")) | C19: =IF(B19="","",INDEX(Prestamos!$B:$B,MATCH(B19,Prestamos!$A:$A,0))) | F19: =IF(B19="","",INDEX(Prestamos!$D:$D,MATCH(B19,Prestamos!$A:$A,0))-SUMIFS($H$1:H1,$B$1:B1,B19)) | G19: =IF(B19="","",F19*INDEX(Prestamos!$E:$E,MATCH(B19,Prestamos!$A:$A,0))) | H19: =IF(B19="","",MAX(0,E19-G19)) | I19: =IF(B19="","",F19-H19)
A20: =IF(B20="","","PG"&TEXT(ROW()-1,"0000")) | C20: =IF(B20="","",INDEX(Prestamos!$B:$B,MATCH(B20,Prestamos!$A:$A,0))) | F20: =IF(B20="","",INDEX(Prestamos!$D:$D,MATCH(B20,Prestamos!$A:$A,0))-SUMIFS($H$1:H1,$B$1:B1,B20)) | G20: =IF(B20="","",F20*INDEX(Prestamos!$E:$E,MATCH(B20,Prestamos!$A:$A,0))) | H20: =IF(B20="","",MAX(0,E20-G20)) | I20: =IF(B20="","",F20-H20)
A21: =IF(B21="","","PG"&TEXT(ROW()-1,"0000")) | C21: =IF(B21="","",INDEX(Prestamos!$B:$B,MATCH(B21,Prestamos!$A:$A,0))) | F21: =IF(B21="","",INDEX(Prestamos!$D:$D,MATCH(B21,Prestamos!$A:$A,0))-SUMIFS($H$1:H1,$B$1:B1,B21)) | G21: =IF(B21="","",F21*INDEX(Prestamos!$E:$E,MATCH(B21,Prestamos!$A:$A,0))) | H21: =IF(B21="","",MAX(0,E21-G21)) | I21: =IF(B21="","",F21-H21)
A22: =IF(B22="","","PG"&TEXT(ROW()-1,"0000")) | C22: =IF(B22="","",INDEX(Prestamos!$B:$B,MATCH(B22,Prestamos!$A:$A,0))) | F22: =IF(B22="","",INDEX(Prestamos!$D:$D,MATCH(B22,Prestamos!$A:$A,0))-SUMIFS($H$1:H1,$B$1:B1,B22)) | G22: =IF(B22="","",F22*INDEX(Prestamos!$E:$E,MATCH(B22,Prestamos!$A:$A,0))) | H22: =IF(B22="","",MAX(0,E22-G22)) | I22: =IF(B22="","",F22-H22)
A23: =IF(B23="","","PG"&TEXT(ROW()-1,"0000")) | C23: =IF(B23="","",INDEX(Prestamos!$B:$B,MATCH(B23,Prestamos!$A:$A,0))) | F23: =IF(B23="","",INDEX(Prestamos!$D:$D,MATCH(B23,Prestamos!$A:$A,0))-SUMIFS($H$1:H1,$B$1:B1,B23)) | G23: =IF(B23="","",F23*INDEX(Prestamos!$E:$E,MATCH(B23,Prestamos!$A:$A,0))) | H23: =IF(B23="","",MAX(0,E23-G23)) | I23: =IF(B23="","",F23-H23)
A24: =IF(B24="","","PG"&TEXT(ROW()-1,"0000")) | C24: =IF(B24="","",INDEX(Prestamos!$B:$B,MATCH(B24,Prestamos!$A:$A,0))) | F24: =IF(B24="","",INDEX(Prestamos!$D:$D,MATCH(B24,Prestamos!$A:$A,0))-SUMIFS($H$1:H1,$B$1:B1,B24)) | G24: =IF(B24="","",F24*INDEX(Prestamos!$E:$E,MATCH(B24,Prestamos!$A:$A,0))) | H24: =IF(B24="","",MAX(0,E24-G24)) | I24: =IF(B24="","",F24-H24)
A25: =IF(B25="","","PG"&TEXT(ROW()-1,"0000")) | C25: =IF(B25="","",INDEX(Prestamos!$B:$B,MATCH(B25,Prestamos!$A:$A,0))) | F25: =IF(B25="","",INDEX(Prestamos!$D:$D,MATCH(B25,Prestamos!$A:$A,0))-SUMIFS($H$1:H1,$B$1:B1,B25)) | G25: =IF(B25="","",F25*INDEX(Prestamos!$E:$E,MATCH(B25,Prestamos!$A:$A,0))) | H25: =IF(B25="","",MAX(0,E25-G25)) | I25: =IF(B25="","",F25-H25)
A26: =IF(B26="","","PG"&TEXT(ROW()-1,"0000")) | C26: =IF(B26="","",INDEX(Prestamos!$B:$B,MATCH(B26,Prestamos!$A:$A,0))) | F26: =IF(B26="","",INDEX(Prestamos!$D:$D,MATCH(B26,Prestamos!$A:$A,0))-SUMIFS($H$1:H1,$B$1:B1,B26)) | G26: =IF(B26="","",F26*INDEX(Prestamos!$E:$E,MATCH(B26,Prestamos!$A:$A,0))) | H26: =IF(B26="","",MAX(0,E26-G26)) | I26: =IF(B26="","",F26-H26)
A27: =IF(B27="","","PG"&TEXT(ROW()-1,"0000")) | C27: =IF(B27="","",INDEX(Prestamos!$B:$B,MATCH(B27,Prestamos!$A:$A,0))) | F27: =IF(B27="","",INDEX(Prestamos!$D:$D,MATCH(B27,Prestamos!$A:$A,0))-SUMIFS($H$1:H1,$B$1:B1,B27)) | G27: =IF(B27="","",F27*INDEX(Prestamos!$E:$E,MATCH(B27,Prestamos!$A:$A,0))) | H27: =IF(B27="","",MAX(0,E27-G27)) | I27: =IF(B27="","",F27-H27)
A28: =IF(B28="","","PG"&TEXT(ROW()-1,"0000")) | C28: =IF(B28="","",INDEX(Prestamos!$B:$B,MATCH(B28,Prestamos!$A:$A,0))) | F28: =IF(B28="","",INDEX(Prestamos!$D:$D,MATCH(B28,Prestamos!$A:$A,0))-SUMIFS($H$1:H1,$B$1:B1,B28)) | G28: =IF(B28="","",F28*INDEX(Prestamos!$E:$E,MATCH(B28,Prestamos!$A:$A,0))) | H28: =IF(B28="","",MAX(0,E28-G28)) | I28: =IF(B28="","",F28-H28)
A29: =IF(B29="","","PG"&TEXT(ROW()-1,"0000")) | C29: =IF(B29="","",INDEX(Prestamos!$B:$B,MATCH(B29,Prestamos!$A:$A,0))) | F29: =IF(B29="","",INDEX(Prestamos!$D:$D,MATCH(B29,Prestamos!$A:$A,0))-SUMIFS($H$1:H1,$B$1:B1,B29)) | G29: =IF(B29="","",F29*INDEX(Prestamos!$E:$E,MATCH(B29,Prestamos!$A:$A,0))) | H29: =IF(B29="","",MAX(0,E29-G29)) | I29: =IF(B29="","",F29-H29)
A30: =IF(B30="","","PG"&TEXT(ROW()-1,"0000")) | C30: =IF(B30="","",INDEX(Prestamos!$B:$B,MATCH(B30,Prestamos!$A:$A,0))) | F30: =IF(B30="","",INDEX(Prestamos!$D:$D,MATCH(B30,Prestamos!$A:$A,0))-SUMIFS($H$1:H1,$B$1:B1,B30)) | G30: =IF(B30="","",F30*INDEX(Prestamos!$E:$E,MATCH(B30,Prestamos!$A:$A,0))) | H30: =IF(B30="","",MAX(0,E30-G30)) | I30: =IF(B30="","",F30-H30)
A31: =IF(B31="","","PG"&TEXT(ROW()-1,"0000")) | C31: =IF(B31="","",INDEX(Prestamos!$B:$B,MATCH(B31,Prestamos!$A:$A,0))) | F31: =IF(B31="","",INDEX(Prestamos!$D:$D,MATCH(B31,Prestamos!$A:$A,0))-SUMIFS($H$1:H1,$B$1:B1,B31)) | G31: =IF(B31="","",F31*INDEX(Prestamos!$E:$E,MATCH(B31,Prestamos!$A:$A,0))) | H31: =IF(B31="","",MAX(0,E31-G31)) | I31: =IF(B31="","",F31-H31)
A32: =IF(B32="","","PG"&TEXT(ROW()-1,"0000")) | C32: =IF(B32="","",INDEX(Prestamos!$B:$B,MATCH(B32,Prestamos!$A:$A,0))) | F32: =IF(B32="","",INDEX(Prestamos!$D:$D,MATCH(B32,Prestamos!$A:$A,0))-SUMIFS($H$1:H1,$B$1:B1,B32)) | G32: =IF(B32="","",F32*INDEX(Prestamos!$E:$E,MATCH(B32,Prestamos!$A:$A,0))) | H32: =IF(B32="","",MAX(0,E32-G32)) | I32: =IF(B32="","",F32-H32)
A33: =IF(B33="","","PG"&TEXT(ROW()-1,"0000")) | C33: =IF(B33="","",INDEX(Prestamos!$B:$B,MATCH(B33,Prestamos!$A:$A,0))) | F33: =IF(B33="","",INDEX(Prestamos!$D:$D,MATCH(B33,Prestamos!$A:$A,0))-SUMIFS($H$1:H1,$B$1:B1,B33)) | G33: =IF(B33="","",F33*INDEX(Prestamos!$E:$E,MATCH(B33,Prestamos!$A:$A,0))) | H33: =IF(B33="","",MAX(0,E33-G33)) | I33: =IF(B33="","",F33-H33)
A34: =IF(B34="","","PG"&TEXT(ROW()-1,"0000")) | C34: =IF(B34="","",INDEX(Prestamos!$B:$B,MATCH(B34,Prestamos!$A:$A,0))) | F34: =IF(B34="","",INDEX(Prestamos!$D:$D,MATCH(B34,Prestamos!$A:$A,0))-SUMIFS($H$1:H1,$B$1:B1,B34)) | G34: =IF(B34="","",F34*INDEX(Prestamos!$E:$E,MATCH(B34,Prestamos!$A:$A,0))) | H34: =IF(B34="","",MAX(0,E34-G34)) | I34: =IF(B34="","",F34-H34)
A35: =IF(B35="","","PG"&TEXT(ROW()-1,"0000")) | C35: =IF(B35="","",INDEX(Prestamos!$B:$B,MATCH(B35,Prestamos!$A:$A,0))) | F35: =IF(B35="","",INDEX(Prestamos!$D:$D,MATCH(B35,Prestamos!$A:$A,0))-SUMIFS($H$1:H1,$B$1:B1,B35)) | G35: =IF(B35="","",F35*INDEX(Prestamos!$E:$E,MATCH(B35,Prestamos!$A:$A,0))) | H35: =IF(B35="","",MAX(0,E35-G35)) | I35: =IF(B35="","",F35-H35)
A36: =IF(B36="","","PG"&TEXT(ROW()-1,"0000")) | C36: =IF(B36="","",INDEX(Prestamos!$B:$B,MATCH(B36,Prestamos!$A:$A,0))) | F36: =IF(B36="","",INDEX(Prestamos!$D:$D,MATCH(B36,Prestamos!$A:$A,0))-SUMIFS($H$1:H1,$B$1:B1,B36)) | G36: =IF(B36="","",F36*INDEX(Prestamos!$E:$E,MATCH(B36,Prestamos!$A:$A,0))) | H36: =IF(B36="","",MAX(0,E36-G36)) | I36: =IF(B36="","",F36-H36)
A37: =IF(B37="","","PG"&TEXT(ROW()-1,"0000")) | C37: =IF(B37="","",INDEX(Prestamos!$B:$B,MATCH(B37,Prestamos!$A:$A,0))) | F37: =IF(B37="","",INDEX(Prestamos!$D:$D,MATCH(B37,Prestamos!$A:$A,0))-SUMIFS($H$1:H1,$B$1:B1,B37)) | G37: =IF(B37="","",F37*INDEX(Prestamos!$E:$E,MATCH(B37,Prestamos!$A:$A,0))) | H37: =IF(B37="","",MAX(0,E37-G37)) | I37: =IF(B37="","",F37-H37)
A38: =IF(B38="","","PG"&TEXT(ROW()-1,"0000")) | C38: =IF(B38="","",INDEX(Prestamos!$B:$B,MATCH(B38,Prestamos!$A:$A,0))) | F38: =IF(B38="","",INDEX(Prestamos!$D:$D,MATCH(B38,Prestamos!$A:$A,0))-SUMIFS($H$1:H1,$B$1:B1,B38)) | G38: =IF(B38="","",F38*INDEX(Prestamos!$E:$E,MATCH(B38,Prestamos!$A:$A,0))) | H38: =IF(B38="","",MAX(0,E38-G38)) | I38: =IF(B38="","",F38-H38)
A39: =IF(B39="","","PG"&TEXT(ROW()-1,"0000")) | C39: =IF(B39="","",INDEX(Prestamos!$B:$B,MATCH(B39,Prestamos!$A:$A,0))) | F39: =IF(B39="","",INDEX(Prestamos!$D:$D,MATCH(B39,Prestamos!$A:$A,0))-SUMIFS($H$1:H1,$B$1:B1,B39)) | G39: =IF(B39="","",F39*INDEX(Prestamos!$E:$E,MATCH(B39,Prestamos!$A:$A,0))) | H39: =IF(B39="","",MAX(0,E39-G39)) | I39: =IF(B39="","",F39-H39)
A40: =IF(B40="","","PG"&TEXT(ROW()-1,"0000")) | C40: =IF(B40="","",INDEX(Prestamos!$B:$B,MATCH(B40,Prestamos!$A:$A,0))) | F40: =IF(B40="","",INDEX(Prestamos!$D:$D,MATCH(B40,Prestamos!$A:$A,0))-SUMIFS($H$1:H1,$B$1:B1,B40)) | G40: =IF(B40="","",F40*INDEX(Prestamos!$E:$E,MATCH(B40,Prestamos!$A:$A,0))) | H40: =IF(B40="","",MAX(0,E40-G40)) | I40: =IF(B40="","",F40-H40)
...
